Workbook

Sheet Dashboard
B2: DASHBOARD ANALISIS HARGA — GEMARTOPUP
B3: Perbandingan modal Indoflaz (Silver/Gold) vs harga kompetitor (Oura Store, Empeshop) & rekomendasi harga jual
B5: Total Produk Aktif | E5: =COUNTA('Analisis Detail'!B2:B351) -> 350
B6: Produk dengan Data Kompetitor | E6: =COUNTIF('Analisis Detail'!N2:N351,"Ada") -> 189
B7: Produk Tanpa Kompetitor (Direct Pricing) | E7: =COUNTIF('Analisis Detail'!N2:N351,"Tidak Ada") -> 161
B8: Rata-rata Margin vs Kompetitor Termurah | E8: =AVERAGEIF('Analisis Detail'!N2:N351,"Ada",'Analisis Detail'!R2:R351) -> 0.021527595
B9: Rata-rata Margin Rekomendasi (semua produk) | E9: =AVERAGE('Analisis Detail'!T2:T351) -> 0.093299295
B12: RINGKASAN PER KATEGORI
B13: Kategori (Sheet Modal) | C13: Jumlah Produk | D13: Ada Kompetitor | E13: Tanpa Kompetitor | F13: Rata2 Margin vs Kompetitor | G13: Rata2 Margin Rekomendasi
B14: UNDAWN INDOFLAZ | C14: =COUNTIF('Analisis Detail'!D2:D351,B14) -> 10 | D14: =COUNTIFS('Analisis Detail'!D2:D351,B14,'Analisis Detail'!N2:N351,"Ada") -> 10 | E14: =COUNTIFS('Analisis Detail'!D2:D351,B14,'Analisis Detail'!N2:N351,"Tidak Ada") -> 0 | F14: =IFERROR(AVERAGEIFS('Analisis Detail'!R2:R351,'Analisis Detail'!D2:D351,B14,'Analisis Detail'!N2:N351,"Ada"),"-") -> 0.089208084 | G14: =AVERAGEIFS('Analisis Detail'!T2:T351,'Analisis Detail'!D2:D351,B14) -> 0.074236844
B15: League of Legend Wild drift IND | C15: =COUNTIF('Analisis Detail'!D2:D351,B15) -> 6 | D15: =COUNTIFS('Analisis Detail'!D2:D351,B15,'Analisis Detail'!N2:N351,"Ada") -> 6 | E15: =COUNTIFS('Analisis Detail'!D2:D351,B15,'Analisis Detail'!N2:N351,"Tidak Ada") -> 0 | F15: =IFERROR(AVERAGEIFS('Analisis Detail'!R2:R351,'Analisis Detail'!D2:D351,B15,'Analisis Detail'!N2:N351,"Ada"),"-") -> 0.029541499 | G15: =AVERAGEIFS('Analisis Detail'!T2:T351,'Analisis Detail'!D2:D351,B15) -> 0.074124468
B16: AOV INDOFLAZ | C16: =COUNTIF('Analisis Detail'!D2:D351,B16) -> 18 | D16: =COUNTIFS('Analisis Detail'!D2:D351,B16,'Analisis Detail'!N2:N351,"Ada") -> 7 | E16: =COUNTIFS('Analisis Detail'!D2:D351,B16,'Analisis Detail'!N2:N351,"Tidak Ada") -> 11 | F16: =IFERROR(AVERAGEIFS('Analisis Detail'!R2:R351,'Analisis Detail'!D2:D351,B16,'Analisis Detail'!N2:N351,"Ada"),"-") -> 0.042005958 | G16: =AVERAGEIFS('Analisis Detail'!T2:T351,'Analisis Detail'!D2:D351,B16) -> 0.094055396
B17: Harry Potter Magic Awakened IND | C17: =COUNTIF('Analisis Detail'!D2:D351,B17) -> 1 | D17: =COUNTIFS('Analisis Detail'!D2:D351,B17,'Analisis Detail'!N2:N351,"Ada") -> 0 | E17: =COUNTIFS('Analisis Detail'!D2:D351,B17,'Analisis Detail'!N2:N351,"Tidak Ada") -> 1 | F17: =IFERROR(AVERAGEIFS('Analisis Detail'!R2:R351,'Analisis Detail'!D2:D351,B17,'Analisis Detail'!N2:N351,"Ada"),"-") -> - | G17: =AVERAGEIFS('Analisis Detail'!T2:T351,'Analisis Detail'!D2:D351,B17) -> 0.10703384
B18: HAGO INDOFLAZ | C18: =COUNTIF('Analisis Detail'!D2:D351,B18) -> 8 | D18: =COUNTIFS('Analisis Detail'!D2:D351,B18,'Analisis Detail'!N2:N351,"Ada") -> 0 | E18: =COUNTIFS('Analisis Detail'!D2:D351,B18,'Analisis Detail'!N2:N351,"Tidak Ada") -> 8 | F18: =IFERROR(AVERAGEIFS('Analisis Detail'!R2:R351,'Analisis Detail'!D2:D351,B18,'Analisis Detail'!N2:N351,"Ada"),"-") -> - | G18: =AVERAGEIFS('Analisis Detail'!T2:T351,'Analisis Detail'!D2:D351,B18) -> 0.10591874
B19: Call Of Duty Mobile INDOFLAZ | C19: =COUNTIF('Analisis Detail'!D2:D351,B19) -> 7 | D19: =COUNTIFS('Analisis Detail'!D2:D351,B19,'Analisis Detail'!N2:N351,"Ada") -> 3 | E19: =COUNTIFS('Analisis Detail'!D2:D351,B19,'Analisis Detail'!N2:N351,"Tidak Ada") -> 4 | F19: =IFERROR(AVERAGEIFS('Analisis Detail'!R2:R351,'Analisis Detail'!D2:D351,B19,'Analisis Detail'!N2:N351,"Ada"),"-") -> 0.0795179 | G19: =AVERAGEIFS('Analisis Detail'!T2:T351,'Analisis Detail'!D2:D351,B19) -> 0.094585408
B20: Honkai Star Rail INDOFLAZ | C20: =COUNTIF('Analisis Detail'!D2:D351,B20) -> 1 | D20: =COUNTIFS('Analisis Detail'!D2:D351,B20,'Analisis Detail'!N2:N351,"Ada") -> 0 | E20: =COUNTIFS('Analisis Detail'!D2:D351,B20,'Analisis Detail'!N2:N351,"Tidak Ada") -> 1 | F20: =IFERROR(AVERAGEIFS('Analisis Detail'!R2:R351,'Analisis Detail'!D2:D351,B20,'Analisis Detail'!N2:N351,"Ada"),"-") -> - | G20: =AVERAGEIFS('Analisis Detail'!T2:T351,'Analisis Detail'!D2:D351,B20) -> 0.10714005
B21: MLBB INDOFLAZ | C21: =COUNTIF('Analisis Detail'!D2:D351,B21) -> 52 | D21: =COUNTIFS('Analisis Detail'!D2:D351,B21,'Analisis Detail'!N2:N351,"Ada") -> 33 | E21: =COUNTIFS('Analisis Detail'!D2:D351,B21,'Analisis Detail'!N2:N351,"Tidak Ada") -> 19 | F21: =IFERROR(AVERAGEIFS('Analisis Detail'!R2:R351,'Analisis Detail'!D2:D351,B21,'Analisis Detail'!N2:N351,"Ada"),"-") -> 0.047957777 | G21: =AVERAGEIFS('Analisis Detail'!T2:T351,'Analisis Detail'!D2:D351,B21) -> 0.086004562
B22: FF INDOFLAZ | C22: =COUNTIF('Analisis Detail'!D2:D351,B22) -> 25 | D22: =COUNTIFS('Analisis Detail'!D2:D351,B22,'Analisis Detail'!N2:N351,"Ada") -> 19 | E22: =COUNTIFS('Analisis Detail'!D2:D351,B22,'Analisis Detail'!N2:N351,"Tidak Ada") -> 6 | F22: =IFERROR(AVERAGEIFS('Analisis Detail'!R2:R351,'Analisis Detail'!D2:D351,B22,'Analisis Detail'!N2:N351,"Ada"),"-") -> 0.11658938 | G22: =AVERAGEIFS('Analisis Detail'!T2:T351,'Analisis Detail'!D2:D351,B22) -> 0.10137139
B23: PUBG INDOFLAZ | C23: =COUNTIF('Analisis Detail'!D2:D351,B23) -> 9 | D23: =COUNTIFS('Analisis Detail'!D2:D351,B23,'Analisis Detail'!N2:N351,"Ada") -> 2 | E23: =COUNTIFS('Analisis Detail'!D2:D351,B23,'Analisis Detail'!N2:N351,"Tidak Ada") -> 7 | F23: =IFERROR(AVERAGEIFS('Analisis Detail'!R2:R351,'Analisis Detail'!D2:D351,B23,'Analisis Detail'!N2:N351,"Ada"),"-") -> 0.017923462 | G23: =AVERAGEIFS('Analisis Detail'!T2:T351,'Analisis Detail'!D2:D351,B23) -> 0.099892499
B24: VALO INDOFLAZZ | C24: =COUNTIF('Analisis Detail'!D2:D351,B24) -> 6 | D24: =COUNTIFS('Analisis Detail'!D2:D351,B24,'Analisis Detail'!N2:N351,"Ada") -> 6 | E24: =COUNTIFS('Analisis Detail'!D2:D351,B24,'Analisis Detail'!N2:N351,"Tidak Ada") -> 0 | F24: =IFERROR(AVERAGEIFS('Analisis Detail'!R2:R351,'Analisis Detail'!D2:D351,B24,'Analisis Detail'!N2:N351,"Ada"),"-") -> 0.021795825 | G24: =AVERAGEIFS('Analisis Detail'!T2:T351,'Analisis Detail'!D2:D351,B24) -> 0.073963913
B25: Point Blank Indoflaz | C25: =COUNTIF('Analisis Detail'!D2:D351,B25) -> 14 | D25: =COUNTIFS('Analisis Detail'!D2:D351,B25,'Analisis Detail'!N2:N351,"Ada") -> 14 | E25: =COUNTIFS('Analisis Detail'!D2:D351,B25,'Analisis Detail'!N2:N351,"Tidak Ada") -> 0 | F25: =IFERROR(AVERAGEIFS('Analisis Detail'!R2:R351,'Analisis Detail'!D2:D351,B25,'Analisis Detail'!N2:N351,"Ada"),"-") -> 0.011500268 | G25: =AVERAGEIFS('Analisis Detail'!T2:T351,'Analisis Detail'!D2:D351,B25) -> 0.073970875
B26: VALO VOUCHER INDOFLAZ | C26: =COUNTIF('Analisis Detail'!D2:D351,B26) -> 6 | D26: =COUNTIFS('Analisis Detail'!D2:D351,B26,'Analisis Detail'!N2:N351,"Ada") -> 0 | E26: =COUNTIFS('Analisis Detail'!D2:D351,B26,'Analisis Detail'!N2:N351,"Tidak Ada") -> 6 | F26: =IFERROR(AVERAGEIFS('Analisis Detail'!R2:R351,'Analisis Detail'!D2:D351,B26,'Analisis Detail'!N2:N351,"Ada"),"-") -> - | G26: =AVERAGEIFS('Analisis Detail'!T2:T351,'Analisis Detail'!D2:D351,B26) -> 0.10694631
B27: Google Play Gift Card INDOFLAZ | C27: =COUNTIF('Analisis Detail'!D2:D351,B27) -> 1 | D27: =COUNTIFS('Analisis Detail'!D2:D351,B27,'Analisis Detail'!N2:N351,"Ada") -> 0 | E27: =COUNTIFS('Analisis Detail'!D2:D351,B27,'Analisis Detail'!N2:N351,"Tidak Ada") -> 1 | F27: =IFERROR(AVERAGEIFS('Analisis Detail'!R2:R351,'Analisis Detail'!D2:D351,B27,'Analisis Detail'!N2:N351,"Ada"),"-") -> - | G27: =AVERAGEIFS('Analisis Detail'!T2:T351,'Analisis Detail'!D2:D351,B27) -> 0.10705244
B28: Google Play Us Region INDOFLAZ | C28: =COUNTIF('Analisis Detail'!D2:D351,B28) -> 4 | D28: =COUNTIFS('Analisis Detail'!D2:D351,B28,'Analisis Detail'!N2:N351,"Ada") -> 0 | E28: =COUNTIFS('Analisis Detail'!D2:D351,B28,'Analisis Detail'!N2:N351,"Tidak Ada") -> 4 | F28: =IFERROR(AVERAGEIFS('Analisis Detail'!R2:R351,'Analisis Detail'!D2:D351,B28,'Analisis Detail'!N2:N351,"Ada"),"-") -> - | G28: =AVERAGEIFS('Analisis Detail'!T2:T351,'Analisis Detail'!D2:D351,B28) -> 0.10714067
B29: iTunes INDOFLAZ | C29: =COUNTIF('Analisis Detail'!D2:D351,B29) -> 7 | D29: =COUNTIFS('Analisis Detail'!D2:D351,B29,'Analisis Detail'!N2:N351,"Ada") -> 0 | E29: =COUNTIFS('Analisis Detail'!D2:D351,B29,'Analisis Detail'!N2:N351,"Tidak Ada") -> 7 | F29: =IFERROR(AVERAGEIFS('Analisis Detail'!R2:R351,'Analisis Detail'!D2:D351,B29,'Analisis Detail'!N2:N351,"Ada"),"-") -> - | G29: =AVERAGEIFS('Analisis Detail'!T2:T351,'Analisis Detail'!D2:D351,B29) -> 0.11211558
B30: Steam Wallet INDOFLAZ | C30: =COUNTIF('Analisis Detail'!D2:D351,B30) -> 8 | D30: =COUNTIFS('Analisis Detail'!D2:D351,B30,'Analisis Detail'!N2:N351,"Ada") -> 7 | E30: =COUNTIFS('Analisis Detail'!D2:D351,B30,'Analisis Detail'!N2:N351,"Tidak Ada") -> 1 | F30: =IFERROR(AVERAGEIFS('Analisis Detail'!R2:R351,'Analisis Detail'!D2:D351,B30,'Analisis Detail'!N2:N351,"Ada"),"-") -> 0.132014 | G30: =AVERAGEIFS('Analisis Detail'!T2:T351,'Analisis Detail'!D2:D351,B30) -> 0.10671266
B31: Spotify Premium Subscription Vo | C31: =COUNTIF('Analisis Detail'!D2:D351,B31) -> 3 | D31: =COUNTIFS('Analisis Detail'!D2:D351,B31,'Analisis Detail'!N2:N351,"Ada") -> 0 | E31: =COUNTIFS('Analisis Detail'!D2:D351,B31,'Analisis Detail'!N2:N351,"Tidak Ada") -> 3 | F31: =IFERROR(AVERAGEIFS('Analisis Detail'!R2:R351,'Analisis Detail'!D2:D351,B31,'Analisis Detail'!N2:N351,"Ada"),"-") -> - | G31: =AVERAGEIFS('Analisis Detail'!T2:T351,'Analisis Detail'!D2:D351,B31) -> 0.10697009
B32: Nintendo Eshop | C32: =COUNTIF('Analisis Detail'!D2:D351,B32) -> 2 | D32: =COUNTIFS('Analisis Detail'!D2:D351,B32,'Analisis Detail'!N2:N351,"Ada") -> 0 | E32: =COUNTIFS('Analisis Detail'!D2:D351,B32,'Analisis Detail'!N2:N351,"Tidak Ada") -> 2 | F32: =IFERROR(AVERAGEIFS('Analisis Detail'!R2:R351,'Analisis Detail'!D2:D351,B32,'Analisis Detail'!N2:N351,"Ada"),"-") -> - | G32: =AVERAGEIFS('Analisis Detail'!T2:T351,'Analisis Detail'!D2:D351,B32) -> 0.10705916
B33: Vidio INDOFLAZ | C33: =COUNTIF('Analisis Detail'!D2:D351,B33) -> 13 | D33: =COUNTIFS('Analisis Detail'!D2:D351,B33,'Analisis Detail'!N2:N351,"Ada") -> 12 | E33: =COUNTIFS('Analisis Detail'!D2:D351,B33,'Analisis Detail'!N2:N351,"Tidak Ada") -> 1 | F33: =IFERROR(AVERAGEIFS('Analisis Detail'!R2:R351,'Analisis Detail'!D2:D351,B33,'Analisis Detail'!N2:N351,"Ada"),"-") -> -0.48766042 | G33: =AVERAGEIFS('Analisis Detail'!T2:T351,'Analisis Detail'!D2:D351,B33) -> 0.10644611
B34: Xbox Indoflaz | C34: =COUNTIF('Analisis Detail'!D2:D351,B34) -> 6 | D34: =COUNTIFS('Analisis Detail'!D2:D351,B34,'Analisis Detail'!N2:N351,"Ada") -> 0 | E34: =COUNTIFS('Analisis Detail'!D2:D351,B34,'Analisis Detail'!N2:N351,"Tidak Ada") -> 6 | F34: =IFERROR(AVERAGEIFS('Analisis Detail'!R2:R351,'Analisis Detail'!D2:D351,B34,'Analisis Detail'!N2:N351,"Ada"),"-") -> - | G34: =AVERAGEIFS('Analisis Detail'!T2:T351,'Analisis Detail'!D2:D351,B34) -> 0.10714385
B35: Hotelmurah INDOLAZ | C35: =COUNTIF('Analisis Detail'!D2:D351,B35) -> 5 | D35: =COUNTIFS('Analisis Detail'!D2:D351,B35,'Analisis Detail'!N2:N351,"Ada") -> 0 | E35: =COUNTIFS('Analisis Detail'!D2:D351,B35,'Analisis Detail'!N2:N351,"Tidak Ada") -> 5 | F35: =IFERROR(AVERAGEIFS('Analisis Detail'!R2:R351,'Analisis Detail'!D2:D351,B35,'Analisis Detail'!N2:N351,"Ada"),"-") -> - | G35: =AVERAGEIFS('Analisis Detail'!T2:T351,'Analisis Detail'!D2:D351,B35) -> 0.10690308
B36: Gontak Whatsapp dan SMS Gateway | C36: =COUNTIF('Analisis Detail'!D2:D351,B36) -> 3 | D36: =COUNTIFS('Analisis Detail'!D2:D351,B36,'Analisis Detail'!N2:N351,"Ada") -> 0 | E36: =COUNTIFS('Analisis Detail'!D2:D351,B36,'Analisis Detail'!N2:N351,"Tidak Ada") -> 3 | F36: =IFERROR(AVERAGEIFS('Analisis Detail'!R2:R351,'Analisis Detail'!D2:D351,B36,'Analisis Detail'!N2:N351,"Ada"),"-") -> - | G36: =AVERAGEIFS('Analisis Detail'!T2:T351,'Analisis Detail'!D2:D351,B36) -> 0.10714286
B37: PLN INDOFLAZ | C37: =COUNTIF('Analisis Detail'!D2:D351,B37) -> 6 | D37: =COUNTIFS('Analisis Detail'!D2:D351,B37,'Analisis Detail'!N2:N351,"Ada") -> 0 | E37: =COUNTIFS('Analisis Detail'!D2:D351,B37,'Analisis Detail'!N2:N351,"Tidak Ada") -> 6 | F37: =IFERROR(AVERAGEIFS('Analisis Detail'!R2:R351,'Analisis Detail'!D2:D351,B37,'Analisis Detail'!N2:N351,"Ada"),"-") -> - | G37: =AVERAGEIFS('Analisis Detail'!T2:T351,'Analisis Detail'!D2:D351,B37) -> 0.1071402
B38: Pulsa Telkomsel INDOFLAZ | C38: =COUNTIF('Analisis Detail'!D2:D351,B38) -> 35 | D38: =COUNTIFS('Analisis Detail'!D2:D351,B38,'Analisis Detail'!N2:N351,"Ada") -> 31 | E38: =COUNTIFS('Analisis Detail'!D2:D351,B38,'Analisis Detail'!N2:N351,"Tidak Ada") -> 4 | F38: =IFERROR(AVERAGEIFS('Analisis Detail'!R2:R351,'Analisis Detail'!D2:D351,B38,'Analisis Detail'!N2:N351,"Ada"),"-") -> 0.036798754 | G38: =AVERAGEIFS('Analisis Detail'!T2:T351,'Analisis Detail'!D2:D351,B38) -> 0.080722586
B39: byU INDOFLAZ | C39: =COUNTIF('Analisis Detail'!D2:D351,B39) -> 20 | D39: =COUNTIFS('Analisis Detail'!D2:D351,B39,'Analisis Detail'!N2:N351,"Ada") -> 0 | E39: =COUNTIFS('Analisis Detail'!D2:D351,B39,'Analisis Detail'!N2:N351,"Tidak Ada") -> 20 | F39: =IFERROR(AVERAGEIFS('Analisis Detail'!R2:R351,'Analisis Detail'!D2:D351,B39,'Analisis Detail'!N2:N351,"Ada"),"-") -> - | G39: =AVERAGEIFS('Analisis Detail'!T2:T351,'Analisis Detail'!D2:D351,B39) -> 0.10733163
B40: Indosat INDOFLAZ | C40: =COUNTIF('Analisis Detail'!D2:D351,B40) -> 19 | D40: =COUNTIFS('Analisis Detail'!D2:D351,B40,'Analisis Detail'!N2:N351,"Ada") -> 16 | E40: =COUNTIFS('Analisis Detail'!D2:D351,B40,'Analisis Detail'!N2:N351,"Tidak Ada") -> 3 | F40: =IFERROR(AVERAGEIFS('Analisis Detail'!R2:R351,'Analisis Detail'!D2:D351,B40,'Analisis Detail'!N2:N351,"Ada"),"-") -> 0.052076812 | G40: =AVERAGEIFS('Analisis Detail'!T2:T351,'Analisis Detail'!D2:D351,B40) -> 0.080040026
B41: Axis INDOFLAZ | C41: =COUNTIF('Analisis Detail'!D2:D351,B41) -> 10 | D41: =COUNTIFS('Analisis Detail'!D2:D351,B41,'Analisis Detail'!N2:N351,"Ada") -> 5 | E41: =COUNTIFS('Analisis Detail'!D2:D351,B41,'Analisis Detail'!N2:N351,"Tidak Ada") -> 5 | F41: =IFERROR(AVERAGEIFS('Analisis Detail'!R2:R351,'Analisis Detail'!D2:D351,B41,'Analisis Detail'!N2:N351,"Ada"),"-") -> 0.095468299 | G41: =AVERAGEIFS('Analisis Detail'!T2:T351,'Analisis Detail'!D2:D351,B41) -> 0.10228547
B42: XL INDOFLAZ | C42: =COUNTIF('Analisis Detail'!D2:D351,B42) -> 11 | D42: =COUNTIFS('Analisis Detail'!D2:D351,B42,'Analisis Detail'!N2:N351,"Ada") -> 4 | E42: =COUNTIFS('Analisis Detail'!D2:D351,B42,'Analisis Detail'!N2:N351,"Tidak Ada") -> 7 | F42: =IFERROR(AVERAGEIFS('Analisis Detail'!R2:R351,'Analisis Detail'!D2:D351,B42,'Analisis Detail'!N2:N351,"Ada"),"-") -> 0.075040208 | G42: =AVERAGEIFS('Analisis Detail'!T2:T351,'Analisis Detail'!D2:D351,B42) -> 0.096660065
B43: TRI INDOFLAZ | C43: =COUNTIF('Analisis Detail'!D2:D351,B43) -> 15 | D43: =COUNTIFS('Analisis Detail'!D2:D351,B43,'Analisis Detail'!N2:N351,"Ada") -> 0 | E43: =COUNTIFS('Analisis Detail'!D2:D351,B43,'Analisis Detail'!N2:N351,"Tidak Ada") -> 15 | F43: =IFERROR(AVERAGEIFS('Analisis Detail'!R2:R351,'Analisis Detail'!D2:D351,B43,'Analisis Detail'!N2:N351,"Ada"),"-") -> - | G43: =AVERAGEIFS('Analisis Detail'!T2:T351,'Analisis Detail'!D2:D351,B43) -> 0.10656715
B44: SMARTFREN INDOFLAZ | C44: =COUNTIF('Analisis Detail'!D2:D351,B44) -> 19 | D44: =COUNTIFS('Analisis Detail'!D2:D351,B44,'Analisis Detail'!N2:N351,"Ada") -> 14 | E44: =COUNTIFS('Analisis Detail'!D2:D351,B44,'Analisis Detail'!N2:N351,"Tidak Ada") -> 5 | F44: =IFERROR(AVERAGEIFS('Analisis Detail'!R2:R351,'Analisis Detail'!D2:D351,B44,'Analisis Detail'!N2:N351,"Ada"),"-") -> 0.036978145 | G44: =AVERAGEIFS('Analisis Detail'!T2:T351,'Analisis Detail'!D2:D351,B44) -> 0.084868587

Sheet UNDAWN INDOFLAZ
A1: PID | B1: KATEGORI | C1: LAYANAN | D1: HARGA | E1: HARGA SILVER | F1: HARGA GOLD | G1: HARGA PRO | H1: STATUS
A2: GU80-S11 | B2: Garena Undawn | C2: RC 80 | D2: Rp. 14.100 | E2: Rp. 13.818 | F2: Rp. 13.684 | G2: Rp. 13.550 | H2: Aktif
A3: GU250-S11 | B3: Garena Undawn | C3: RC 250 | D3: Rp. 42.300 | E3: Rp. 41.049 | F3: Rp. 40.647 | G3: Rp. 40.647 | H3: Aktif
A4: GU450-S11 | B4: Garena Undawn | C4: RC 450 | D4: Rp. 70.500 | E4: Rp. 69.086 | F4: Rp. 68.415 | G4: Rp. 67.744 | H4: Aktif
A5: GU920-S11 | B5: Garena Undawn | C5: RC 920 | D5: Rp. 140.000 | E5: Rp. 137.249 | F5: Rp. 135.917 | G5: Rp. 134.584 | H5: Aktif
A6: GU1850-S11 | B6: Garena Undawn | C6: RC 1850 | D6: Rp. 280.800 | E6: Rp. 275.418 | F6: Rp. 272.744 | G6: Rp. 270.070 | H6: Aktif
A7: GU2800-S11 | B7: Garena Undawn | C7: RC 2800 | D7: Rp. 417.700 | E7: Rp. 413.588 | F7: Rp. 409.572 | G7: Rp. 405.557 | H7: Aktif
A8: GU4750-S11 | B8: Garena Undawn | C8: RC 4750 | D8: Rp. 696.700 | E8: Rp. 689.926 | F8: Rp. 683.228 | G8: Rp. 676.530 | H8: Aktif
A9: GU9600-S11 | B9: Garena Undawn | C9: RC 9600 | D9: Rp. 1.380.800 | E9: Rp. 1.367.368 | F9: Rp. 1.353.962 | G9: Rp. 1.347.259 | H9: Aktif
A10: GU33000-S11 | B10: Garena Undawn | C10: RC 33000 | D10: Rp. 4.605.700 | E10: Rp. 4.560.930 | F10: Rp. 4.516.215 | G10: Rp. 4.493.858 | H10: Aktif
A11: GU66500-S11 | B11: Garena Undawn | C11: RC 66500 | D11: Rp. 9.211.300 | E11: Rp. 9.121.860 | F11: Rp. 9.032.430 | G11: Rp. 8.987.715 | H11: Aktif

Sheet UNDAWN OURA STORE
A1: Membership
A2: Select a variant list
A3: Ace Fund
A4: 143744
A5: Top Up Instant
A6: Top Up Instant
A7: RC 80
A8: 15008
A9: RC 250
A10: 43756
A11: RC 450
A12: 75037
A13: RC 920
A14: 149072
A15: RC 1850
A16: 299143
A17: RC 2800
A18: 449215
A19: RC 4750
A20: 749359
A21: RC 9600
A22: 1499716
A23: RC 33000
A24: 5002388
A25: RC 66500
A26: 10004775

Sheet League of Legend Wild drift IND
A1: PID | B1: KATEGORI | C1: LAYANAN | D1: HARGA | E1: HARGA SILVER | F1: HARGA GOLD | G1: HARGA PRO | H1: STATUS
A2: LOL425-S10 | B2: League of Legends Wild Rift | C2: 425 Cores | D2: Rp. 53.700 | E2: Rp. 53.172 | F2: Rp. 52.656 | G2: Rp. 52.140 | H2: Aktif
A3: LOL1000-S10 | B3: League of Legends Wild Rift | C3: 1000 Cores | D3: Rp. 119.900 | E3: Rp. 118.687 | F3: Rp. 117.535 | G3: Rp. 116.383 | H3: Aktif
A4: LOL1850-S10 | B4: League of Legends Wild Rift | C4: 1850 Cores | D4: Rp. 215.800 | E4: Rp. 213.637 | F4: Rp. 211.563 | G4: Rp. 209.489 | H4: Aktif
A5: LOL3275-S10 | B5: League of Legends Wild Rift | C5: 3275 Cores | D5: Rp. 378.700 | E5: Rp. 375.051 | F5: Rp. 371.410 | G5: Rp. 367.769 | H5: Aktif
A6: LOL4800-S10 | B6: League of Legends Wild Rift | C6: 4800 Cores | D6: Rp. 541.700 | E6: Rp. 536.466 | F6: Rp. 531.257 | G6: Rp. 526.049 | H6: Aktif
A7: LOL10000-S10 | B7: League of Legends Wild Rift | C7: 10000 Cores | D7: Rp. 1.082.400 | E7: Rp. 1.071.980 | F7: Rp. 1.061.573 | G7: Rp. 1.051.165 | H7: Aktif

Sheet AOV INDOFLAZ
A1: PID | B1: KATEGORI | C1: LAYANAN | D1: HARGA | E1: HARGA SILVER | F1: HARGA GOLD | G1: HARGA PRO | H1: STATUS
A2: AOV40-S11 | B2: Arena Of Valor | C2: 40 Vouchers | D2: Rp. 9.600 | E2: Rp. 9.464 | F2: Rp. 9.373 | G2: Rp. 9.282 | H2: Aktif
A3: AOV90-S11 | B3: Arena Of Valor | C3: 90 Vouchers | D3: Rp. 19.200 | E3: Rp. 18.928 | F3: Rp. 18.746 | G3: Rp. 18.564 | H3: Aktif
A4: AOV230-S11 | B4: Arena Of Valor | C4: 230 Vouchers | D4: Rp. 47.800 | E4: Rp. 47.320 | F4: Rp. 46.865 | G4: Rp. 46.410 | H4: Aktif
A5: AOV470-S11 | B5: Arena Of Valor | C5: 470 Vouchers | D5: Rp. 95.600 | E5: Rp. 94.640 | F5: Rp. 93.730 | G5: Rp. 92.820 | H5: Aktif
A6: AOV600-S11 | B6: Arena Of Valor | C6: 600 Vouchers | D6: Rp. 124.300 | E6: Rp. 123.032 | F6: Rp. 121.849 | G6: Rp. 120.666 | H6: Aktif
A7: AOV700-S11 | B7: Arena Of Valor | C7: 700 Vouchers | D7: Rp. 143.400 | E7: Rp. 141.960 | F7: Rp. 140.595 | G7: Rp. 139.230 | H7: Aktif
A8: AOV950-S11 | B8: Arena Of Valor | C8: 950 Vouchers | D8: Rp. 191.100 | E8: Rp. 189.280 | F8: Rp. 187.460 | G8: Rp. 185.640 | H8: Aktif
A9: AOV1030-S11 | B9: Arena Of Valor | C9: 1030 Vouchers | D9: Rp. 210.300 | E9: Rp. 208.208 | F9: Rp. 206.206 | G9: Rp. 204.204 | H9: Aktif
A10: AOV1420-S11 | B10: Arena Of Valor | C10: 1420 Vouchers | D10: Rp. 286.700 | E10: Rp. 283.920 | F10: Rp. 281.190 | G10: Rp. 278.460 | H10: Aktif
A11: AOV1430-S11 | B11: Arena Of Valor | C11: 1430 Vouchers | D11: Rp. 286.700 | E11: Rp. 283.920 | F11: Rp. 281.190 | G11: Rp. 278.460 | H11: Aktif
A12: AOV1440-S11 | B12: Arena Of Valor | C12: 1440 Vouchers | D12: Rp. 296.300 | E12: Rp. 293.384 | F12: Rp. 290.563 | G12: Rp. 287.742 | H12: Aktif
... A19: AOV9420-S11 | B19: Arena Of Valor | C19: 9420 Vouchers | D19: Rp. 1.901.500 | E19: Rp. 1.883.336 | F19: Rp. 1.865.227 | G19: Rp. 1.847.118 | H19: Aktif

Sheet AOV OURA STORE
A1: Top Up Instant
A2: Select a variant list
A3: 40 Vouchers
A4: 9785
A5: 90 Vouchers
A6: 19568
A7: 230 Vouchers
A8: 48920
A9: 470 Vouchers
A10: 97838
A11: 950 Vouchers
A12: 195674
A13: 1430 Vouchers
A14: 293511
A15: 2390 Vouchers
A16: 489185
A17: 4800 Vouchers
A18: 988152
A19: 24050 Vouchers
A20: 4930973
A21: 48200 Vouchers
A22: 9881513

Sheet Harry Potter Magic Awakened IND
A1: PID | B1: KATEGORI | C1: LAYANAN | D1: HARGA | E1: HARGA SILVER | F1: HARGA GOLD | G1: HARGA PRO | H1: STATUS
A2: HP1980-S11 | B2: Harry Potter: Magic Awakened | C2: 1980 + 380 Jewels | D2: Rp. 368.722 | E2: Rp. 365.142 | F2: Rp. 361.562 | G2: Rp. 359.772 | H2: Aktif

Sheet Harry Potter Magic Awakened OUR
A1: Special Item
A2: Select a variant list
A3: Gold Supply Pack
A4: 71249
A5: Monthly Card
A6: 72300
A7: Ruby Key Pack
A8: 141382
A9: Clockturn Key Pack
A10: 211516
A11: Golden Key Pack
A12: 283876
A13: Top Up Instant
A14: Select a variant list
A15: 60 Jawels
A16: 16804
A17: 300 Jawels
A18: 82969
A19: 750 (680+70) Jawels
A20: 166987
A21: 1145 (980+165) Jawels
A22: 261507
A23: 1550 (1280+270) Jawels
A24: 345525
A25: 2360 (1980+380) Jawels
A26: 503059
A27: 4060 (3280+780) Jawels
A28: 839131
A29: 8480 (6480+2000) Jawels
A30: 1679311

Sheet HAGO INDOFLAZ
A1: PID | B1: KATEGORI | C1: LAYANAN | D1: HARGA | E1: HARGA SILVER | F1: HARGA GOLD | G1: HARGA PRO | H1: STATUS
A2: HAGO6-S7 | B2: Hago | C2: 6 Diamonds | D2: Rp. 2.100 | E2: Rp. 2.028 | F2: Rp. 1.989 | G2: Rp. 1.960 | H2: Aktif
A3: HAGO46-S7 | B3: Hago | C3: 46 Diamonds | D3: Rp. 15.600 | E3: Rp. 15.443 | F3: Rp. 15.146 | G3: Rp. 14.924 | H3: Aktif
A4: HAGO91-S7 | B4: Hago | C4: 91 Diamonds | D4: Rp. 31.200 | E4: Rp. 30.885 | F4: Rp. 30.291 | G4: Rp. 29.846 | H4: Aktif
A5: HAGO228-S7 | B5: Hago | C5: 228 Diamonds | D5: Rp. 78.000 | E5: Rp. 77.213 | F5: Rp. 75.728 | G5: Rp. 74.615 | H5: Aktif
A6: HAGO381-S7 | B6: Hago | C6: 381 Diamonds | D6: Rp. 130.000 | E6: Rp. 128.688 | F6: Rp. 126.213 | G6: Rp. 124.357 | H6: Aktif
A7: HAGO915-S7 | B7: Hago | C7: 915 Diamonds | D7: Rp. 311.900 | E7: Rp. 308.849 | F7: Rp. 302.910 | G7: Rp. 298.455 | H7: Aktif
A8: HAGO1680-S7 | B8: Hago | C8: 1680 Diamonds | D8: Rp. 571.700 | E8: Rp. 566.224 | F8: Rp. 555.335 | G8: Rp. 547.169 | H8: Aktif
A9: HAGO3362-S7 | B9: Hago | C9: 3362 Diamonds | D9: Rp. 1.143.400 | E9: Rp. 1.132.447 | F9: Rp. 1.110.669 | G9: Rp. 1.094.336 | H9: Aktif

Sheet Call Of Duty Mobile INDOFLAZ
A1: PID | B1: KATEGORI | C1: LAYANAN | D1: HARGA | E1: HARGA SILVER | F1: HARGA GOLD | G1: HARGA PRO | H1: STATUS
A2: CODM128-S8 | B2: Call Of Duty Mobile | C2: 128 CP | D2: Rp. 18.100 | E2: Rp. 17.899 | F2: Rp. 17.727 | G2: Rp. 17.297 | H2: Aktif
A3: CODM321-S8 | B3: Call Of Duty Mobile | C3: 321 CP | D3: Rp. 47.900 | E3: Rp. 47.346 | F3: Rp. 46.891 | G3: Rp. 45.753 | H3: Aktif
A4: CODM528-S8 | B4: Call Of Duty Mobile | C4: 528 CP | D4: Rp. 95.800 | E4: Rp. 94.822 | F4: Rp. 93.911 | G4: Rp. 91.631 | H4: Aktif
A5: CODM1056-S8 | B5: Call Of Duty Mobile | C5: 1056 CP | D5: Rp. 199.500 | E5: Rp. 197.522 | F5: Rp. 195.623 | G5: Rp. 190.875 | H5: Aktif
A6: CODM1584-S8 | B6: Call Of Duty Mobile | C6: 1584 CP | D6: Rp. 275.700 | E6: Rp. 273.026 | F6: Rp. 270.401 | G6: Rp. 263.838 | H6: Aktif
A7: CODM2059-S8 | B7: Call Of Duty Mobile | C7: 2059 CP | D7: Rp. 281.300 | E7: Rp. 278.608 | F7: Rp. 275.929 | G7: Rp. 269.232 | H7: Aktif
A8: CODM38280-S8 | B8: Call Of Duty Mobile | C8: 38280 CP | D8: Rp. 4.916.800 | E8: Rp. 4.869.878 | F8: Rp. 4.823.053 | G8: Rp. 4.705.988 | H8: Aktif

Sheet Call Of Duty Mobile OURA STORE
A1: Top Up Instant
A2: Select a variant list
A3: 31 CP
A4: 4893
A5: 63 CP
A6: 10006
A7: 128 CP
A8: 20011
A9: 321 CP
A10: 50025
A11: 645 CP
A12: 100049
A13: 800 CP
A14: 117405
A15: 1373 CP
A16: 200096
A17: 2060 CP
A18: 300144
A19: 2750 CP
A20: 371781
A21: 3564 CP
A22: 500240
A23: 5618 CP
A24: 714210
A25: 7656 CP
A26: 1000478
A27: 15312 CP
A28: 2056230
A29: 38280 CP
A30: 5140575
A31: 76560 CP
A32: 10281150

Sheet Honkai  Star Rail INDOFLAZ
A1: PID | B1: KATEGORI | C1: LAYANAN | D1: HARGA | E1: HARGA SILVER | F1: HARGA GOLD | G1: HARGA PRO | H1: STATUS
A2: HSTR32400-S11 | B2: Honkai : Star Rail | C2: 6480 + 1600 Oneiric Shard x 5 | D2: Rp. 5.847.308 | E2: Rp. 5.790.538 | F2: Rp. 5.733.768 | G2: Rp. 5.705.383 | H2: Aktif

Sheet Honkai  Star Rail OURA STORE
A1: Oneiric Shard (Indonesia)
A2: Select a variant list
A3: 60 Oneiric Shard (ID)
A4: 16000
A5: 330 (300+30) Oneiric Shard (ID)
A6: 79000
A7: 1090 (980+110) Oneiric Shard (ID)
A8: 249000
A9: 2240 (1980+260) Oneiric Shard (ID)
A10: 479000
A11: 3880 (3280+600) Oneiric Shard (ID)
A12: 799000
A13: 8080 (6480+1600) Oneiric Shard (ID)
A14: 1599000

Sheet League of Legend Wild drift OUR
A1: Region Indonesia
A2: Select a variant list
A3: 425 Wild Cores
A4: 54259
A5: 1000 Wild Cores
A6: 121113
A7: 1850 Wild Cores
A8: 218003
A9: 3275 Wild Cores
A10: 382716
A11: 4800 Wild Cores
A12: 547428
A13: 10000 Wild Cores
A14: 1093887
A15: Region Malaysia
A16: Select a variant list
A17: 425 Wild Cores
A18: 70384
A19: 1000 Wild Cores
A20: 154545
A21: 1850 Wild Cores
A22: 282649
A23: 3275 Wild Cores
A24: 494915
A25: 4800 Wild Cores
A26: 707180
A27: 10000 Wild Cores
A28: 1414732
A29: Region Philippines
A30: Select a variant list
A31: 425 Cores
A32: 57227
A33: 1000 Cores
A34: 128473
A35: 1850 Cores
A36: 234341
A37: 3275 Cores
A38: 409166
A39: 4800 Cores
A40: 586566
...

Sheet MLBB INDOFLAZ
A1: PID | B1: KATEGORI | C1: LAYANAN | D1: HARGA | E1: HARGA SILVER | F1: HARGA GOLD | G1: HARGA PRO | H1: STATUS
A2: ML3-S7 | B2: Mobile Legends | C2: 3 Diamonds | D2: Rp. 1.100 | E2: Rp. 1.030 | F2: Rp. 1.020 | G2: Rp. 1.010 | H2: Aktif
A3: ML5-S7 | B3: Mobile Legends | C3: 5 Diamonds | D3: Rp. 1.600 | E3: Rp. 1.478 | F3: Rp. 1.463 | G3: Rp. 1.449 | H3: Aktif
A4: ML10-S7 | B4: Mobile Legends | C4: 10 Diamonds (9 + 1 Bonus) | D4: Rp. 3.100 | E4: Rp. 2.956 | F4: Rp. 2.927 | G4: Rp. 2.898 | H4: Aktif
A5: ML14-S7 | B5: Mobile Legends | C5: 14 Diamonds (13 + 1 Bonus) | D5: Rp. 4.100 | E5: Rp. 3.974 | F5: Rp. 3.936 | G5: Rp. 3.897 | H5: Aktif
A6: ML19-S7 | B6: Mobile Legends | C6: 19 Diamonds (18 + 1 Bonus) | D6: Rp. 5.600 | E6: Rp. 5.418 | F6: Rp. 5.366 | G6: Rp. 5.313 | H6: Aktif
A7: ML36-S7 | B7: Mobile Legends | C7: 36 Diamonds (33 + 3 Bonus) | D7: Rp. 10.200 | E7: Rp. 9.935 | F7: Rp. 9.838 | G7: Rp. 9.742 | H7: Aktif
A8: ML46-S7 | B8: Mobile Legends | C8: 46 Diamonds (42 + 4 Bonus) | D8: Rp. 13.200 | E8: Rp. 12.889 | F8: Rp. 12.764 | G8: Rp. 12.639 | H8: Aktif
A9: ML54-S7 | B9: Mobile Legends | C9: 54 Diamonds (50 + 4 Bonus) | D9: Rp. 15.200 | E9: Rp. 14.902 | F9: Rp. 14.757 | G9: Rp. 14.612 | H9: Aktif
A10: ML71-S7 | B10: Mobile Legends | C10: 71 Diamonds (64 + 7 Bonus) | D10: Rp. 19.600 | E10: Rp. 19.211 | F10: Rp. 19.025 | G10: Rp. 18.838 | H10: Aktif
A11: ML74-S7 | B11: Mobile Legends | C11: 74 Diamonds (67 + 7 Bonus) | D11: Rp. 20.300 | E11: Rp. 19.867 | F11: Rp. 19.674 | G11: Rp. 19.481 | H11: Aktif
A12: ML85-S7 | B12: Mobile Legends | C12: 85 Diamonds (77 + 8 Bonus) | D12: Rp. 23.100 | E12: Rp. 22.659 | F12: Rp. 22.439 | G12: Rp. 22.219 | H12: Aktif
... A53: ML19320-S7 | B53: Mobile Legends | C53: 19320 Diamonds (16012 + 3308 Bonus) | D53: Rp. 4.809.800 | E53: Rp. 4.718.168 | F53: Rp. 4.672.360 | G53: Rp. 4.626.553 | H53: Aktif

Sheet MLBB OURA STORE
A1: Top Up Instant✨
A2: Select a variant list
A3: 5 (5+0) Diamonds
A4: 1530
A5: 10 (9+1) Diamonds
A6: 3111
A7: 12 (11+1) Diamonds
A8: 3567
A9: 14 (13+1) Diamonds
A10: 4148
A11: 15 (15+0) Diamonds
A12: 4588
A13: 17 (16+1) Diamonds
A14: 4779
A15: 18 (17+1) Diamonds
A16: 5185
A17: 19 (17+2) Diamonds
A18: 5606
A19: 20 (18+2) Diamonds
A20: 6221
A21: 22 (20+2) Diamonds
A22: 6677
A23: 28 (25+3) Diamonds
A24: 8153
A25: 30 (28+2) Diamonds
A26: 8751
A27: 33 (30+3) Diamonds
A28: 9559
A29: 36 (33+3) Diamonds
A30: 10367
A31: 44 (40+4) Diamonds
A32: 12228
A33: 45 (42+3) Diamonds
A34: 13390
A35: 46 (42+4) Diamonds
A36: 13477
A37: 50 (46+4) Diamonds
A38: 14337
A39: 54 (49+5) Diamonds
A40: 15339
...

Sheet MLBB EMPESHOP
A1: 592 Diamonds ( 512 + 80 Bonus )
A2: Rp 163.734,-
A3: 10% OFF
A4: 6030 Diamonds ( 5124 + 906 Bonus )
A5: Rp 1.579.837,-
A6: 20% OFF
A7: Weekly Diamond Pass x5
A8: Rp 144.924,-
A9: 20% OFF
A10: Weekly Diamond Pass x3
A11: Rp 86.955,-
A12: 20% OFF
... A70: Rp 5.428.479,-

Sheet FF INDOFLAZ
A1: PID | B1: KATEGORI | C1: LAYANAN | D1: HARGA | E1: HARGA SILVER | F1: HARGA GOLD | G1: HARGA PRO | H1: STATUS
A2: FF5-S9 | B2: Free Fire | C2: 5 Diamond | D2: Rp. 900 | E2: Rp. 822 | F2: Rp. 814 | G2: Rp. 806 | H2: Aktif
A3: FF10-S9 | B3: Free Fire | C3: 10 Diamond | D3: Rp. 1.700 | E3: Rp. 1.638 | F3: Rp. 1.622 | G3: Rp. 1.606 | H3: Aktif
A4: FF20-S9 | B4: Free Fire | C4: 20 Diamond | D4: Rp. 3.300 | E4: Rp. 3.199 | F4: Rp. 3.168 | G4: Rp. 3.137 | H4: Aktif
A5: FF30-S9 | B5: Free Fire | C5: 30 Diamond | D5: Rp. 4.900 | E5: Rp. 4.827 | F5: Rp. 4.780 | G5: Rp. 4.733 | H5: Aktif
A6: FF40-S9 | B6: Free Fire | C6: 40 Diamond | D6: Rp. 6.500 | E6: Rp. 6.355 | F6: Rp. 6.293 | G6: Rp. 6.231 | H6: Aktif
A7: FF50-S9 | B7: Free Fire | C7: 50 Diamond | D7: Rp. 6.700 | E7: Rp. 6.538 | F7: Rp. 6.474 | G7: Rp. 6.411 | H7: Aktif
A8: FF55-S9 | B8: Free Fire | C8: 55 Diamond | D8: Rp. 7.500 | E8: Rp. 7.355 | F8: Rp. 7.283 | G8: Rp. 7.212 | H8: Aktif
A9: FF100-S9 | B9: Free Fire | C9: 100 Diamond | D9: Rp. 13.200 | E9: Rp. 13.050 | F9: Rp. 12.923 | G9: Rp. 12.796 | H9: Aktif
A10: FF140-S9 | B10: Free Fire | C10: 140 Diamond | D10: Rp. 17.300 | E10: Rp. 17.088 | F10: Rp. 16.922 | G10: Rp. 16.756 | H10: Aktif
A11: FFMM-S9 | B11: Free Fire | C11: Membership Mingguan | D11: Rp. 27.100 | E11: Rp. 26.813 | F11: Rp. 26.553 | G11: Rp. 26.293 | H11: Aktif
A12: FF210-S9 | B12: Free Fire | C12: 210 Diamond | D12: Rp. 27.500 | E12: Rp. 27.203 | F12: Rp. 26.939 | G12: Rp. 26.675 | H12: Aktif
... A26: FF73100-S9 | B26: Free Fire | C26: 73100 Diamond | D26: Rp. 9.464.100 | E26: Rp. 9.373.026 | F26: Rp. 9.282.026 | G26: Rp. 9.191.026 | H26: Aktif

Sheet FF OURA STORE
A1: 5 Diamonds
A2: 974
A3: 12 Diamonds
A4: 1948
A5: 15 Diamonds
A6: 2922
A7: 20 Diamonds
A8: 3895
A9: 25 Diamonds
A10: 4869
A11: 30 Diamonds
A12: 5843
A13: 50 Diamonds
A14: 7787
A15: 55 Diamonds
A16: 8761
A17: 70 Diamonds
A18: 9733
A19: 75 Diamonds
A20: 10707
A21: 80 Diamonds
A22: 11681
A23: 90 Diamonds
A24: 13628
A25: 95 Diamonds
A26: 14602
A27: 100 Diamonds
A28: 15575
A29: 120 Diamonds
A30: 17520
A31: 125 Diamonds
A32: 18493
A33: 140 Diamonds
A34: 19465
A35: 145 Diamonds
A36: 20439
A37: 150 Diamonds
A38: 21412
A39: 160 Diamonds
A40: 23360
...

Sheet FF EMPE SHOP
A1: 2000 Diamonds
A2: Rp 282.827,-
A3: 15% OFF
A4: 20 Diamonds
A5: Rp 4.026,-
A6: 55 Diamonds
A7: Rp 9.059,-
A8: 70 Diamonds
A9: Rp 10.999,-
A10: 140 Diamond
A11: Rp 19.910,-
A12: 355 Diamond
... A25: 15% OFF

Sheet PUBG OURA STORE
A1: All Region
A2: Select a variant list
A3: 60 UC
A4: 17286
A5: 325 UC
A6: 86816
A7: 660 UC
A8: 173632
A9: 1800 UC
A10: 434467
A11: 3850 UC
A12: 868933
A13: 8100 UC
A14: 1738057
A15: Region Indo
A16: Region Indo
A17: 60 UC (ID)
A18: 17031
A19: 120 UC (ID)
A20: 34061
A21: 180 UC (ID)
A22: 51091
A23: 240 UC (ID)
A24: 68121
A25: 325 (300+25) UC (ID)
A26: 86213
A27: 385 (360+25) UC (ID)
A28: 103243
A29: 445 (420+25) UC (ID)
A30: 120273
A31: 505 (480+25) UC (ID)
A32: 137303
A33: 565 (540+25) UC (ID)
A34: 154333
A35: 660 (600+60) UC (ID)
A36: 172425
A37: 720 (660+60) UC (ID)
A38: 189455
A39: 780 (720+60) UC (ID)
A40: 206485
...

Sheet PUBG INDOFLAZ
A1: PID | B1: KATEGORI | C1: LAYANAN | D1: HARGA | E1: HARGA SILVER | F1: HARGA GOLD | G1: HARGA PRO | H1: STATUS
A2: 1343 | B2: Pubg Mobile | C2: 60 UC | D2: Rp. 17.400 | E2: Rp. 17.047 | F2: Rp. 16.726 | G2: Rp. 16.404 | H2: Aktif
A3: 1459 | B3: Pubg Mobile | C3: 120 UC | D3: Rp. 34.800 | E3: Rp. 34.093 | F3: Rp. 33.450 | G3: Rp. 32.807 | H3: Aktif
A4: 1344 | B4: Pubg Mobile | C4: 300 + 25 Bonus UC | D4: Rp. 87.700 | E4: Rp. 86.008 | F4: Rp. 84.385 | G4: Rp. 82.762 | H4: Aktif
A5: 1345 | B5: Pubg Mobile | C5: 600 + 60 Bonus UC | D5: Rp. 175.500 | E5: Rp. 172.209 | F5: Rp. 168.960 | G5: Rp. 165.711 | H5: Aktif
A6: 1125 | B6: Pubg Mobile | C6: 3000 + 850 Bonus UC | D6: Rp. 878.100 | E6: Rp. 861.819 | F6: Rp. 845.558 | G6: Rp. 829.297 | H6: Aktif
A7: 1342 | B7: Pubg Mobile | C7: 6000 + 2100 Bonus UC | D7: Rp. 1.756.400 | E7: Rp. 1.723.831 | F7: Rp. 1.691.306 | G7: Rp. 1.658.781 | H7: Aktif
A8: 1454 | B8: Pubg Mobile | C8: 12000 + 4200 Bonus UC | D8: Rp. 3.512.800 | E8: Rp. 3.447.660 | F8: Rp. 3.382.610 | G8: Rp. 3.317.560 | H8: Aktif
A9: 1455 | B9: Pubg Mobile | C9: 18000 + 6300 Bonus UC | D9: Rp. 5.269.100 | E9: Rp. 5.171.490 | F9: Rp. 5.073.915 | G9: Rp. 4.976.340 | H9: Aktif
A10: 1456 | B10: Pubg Mobile | C10: 24000 + 8400 Bonus UC | D10: Rp. 7.025.500 | E10: Rp. 6.895.320 | F10: Rp. 6.765.219 | G10: Rp. 6.635.119 | H10: Aktif

Sheet PUBG EMPESHOP
A1: 120 UC
A2: Rp 32.457,-
A3: 360 + 25 UC
A4: Rp 105.807,-
A5: 600 + 60 UC
A6: Rp 162.280,-
A7: 1080 + 85 UC
A8: Rp 292.104,-
A9: 10% OFF
A10: 1680 + 300 UC
A11: Rp 454.382,-
A12: 2400 + 385 UC
... A15: Rp 1.309.930,-

Sheet VALO INDOFLAZZ
A1: PID | B1: KATEGORI | C1: LAYANAN | D1: HARGA | E1: HARGA SILVER | F1: HARGA GOLD | G1: HARGA PRO | H1: STATUS
A2: VAL475-S11 | B2: Valorant | C2: 475 Points | D2: Rp. 54.700 | E2: Rp. 53.597 | F2: Rp. 53.076 | G2: Rp. 52.556 | H2: Aktif
A3: VAL1000-S11 | B3: Valorant | C3: 1000 Points | D3: Rp. 109.300 | E3: Rp. 107.193 | F3: Rp. 106.152 | G3: Rp. 105.111 | H3: Aktif
A4: VAL2050-S11 | B4: Valorant | C4: 2050 Points | D4: Rp. 218.600 | E4: Rp. 214.386 | F4: Rp. 212.304 | G4: Rp. 210.223 | H4: Aktif
A5: VAL3650-S11 | B5: Valorant | C5: 3650 Points | D5: Rp. 379.600 | E5: Rp. 372.303 | F5: Rp. 368.689 | G5: Rp. 365.074 | H5: Aktif
A6: VAL5350-S11 | B6: Valorant | C6: 5350 Points | D6: Rp. 545.400 | E6: Rp. 535.006 | F6: Rp. 529.812 | G6: Rp. 524.618 | H6: Aktif
A7: VAL11000-S11 | B7: Valorant | C7: 11000 Points | D7: Rp. 1.072.300 | E7: Rp. 1.051.827 | F7: Rp. 1.041.615 | G7: Rp. 1.031.403 | H7: Aktif

Sheet VALO OURA STORE
A1: Region Indonesia
A2: Select a variant list
A3: 475 Points
A4: 54259
A5: 1000 Points
A6: 108518
A7: 950 Points
A8: 108518
A9: 1475 Points
A10: 162777
A11: 2050 Points
A12: 217034
A13: 2000 Points
A14: 217035
A15: 2525 Points
A16: 271293
A17: 3050 Points
A18: 325552
A19: 3650 Points
A20: 376902
A21: 4125 Points
A22: 431161
A23: 4100 Points
A24: 434068
A25: 4650 Points
A26: 485420
A27: 5350 Points
A28: 541615
A29: 5700 Points
A30: 593936
A31: 5825 Points
A32: 595873
A33: 6350 Points
A34: 650132
A35: 7300 Points
A36: 753804
A37: 7400 Points
A38: 758649
A39: 8400 Points
A40: 867166
...

Sheet Point Blank Indoflaz
A1: PID | B1: KATEGORI | C1: LAYANAN | D1: HARGA | E1: HARGA SILVER | F1: HARGA GOLD | G1: HARGA PRO | H1: STATUS
A2: VCPB1200-S7 | B2: Voucher Point Blank | C2: 1200 PB Cash | D2: Rp. 9.400 | E2: Rp. 9.065 | F2: Rp. 8.976 | G2: Rp. 8.932 | H2: Aktif
A3: VCPB2400-S7 | B3: Voucher Point Blank | C3: 2400 PB Cash | D3: Rp. 18.400 | E3: Rp. 18.130 | F3: Rp. 17.952 | G3: Rp. 17.863 | H3: Aktif
A4: VCPB1200-S11 | B4: Voucher Point Blank | C4: 1200 PB Cash | D4: Rp. 18.600 | E4: Rp. 18.334 | F4: Rp. 18.156 | G4: Rp. 17.978 | H4: Aktif
A5: VCPB2400-S110 | B5: Voucher Point Blank | C5: 2400 PB Cash | D5: Rp. 18.720 | E5: Rp. 18.540 | F5: Rp. 18.360 | G5: Rp. 18.180 | H5: Aktif
A6: VCPB6000-S7 | B6: Voucher Point Blank | C6: 6000 PB Cash | D6: Rp. 45.800 | E6: Rp. 45.325 | F6: Rp. 44.881 | G6: Rp. 44.659 | H6: Aktif
A7: VCPB6000-S11 | B7: Voucher Point Blank | C7: 6000 PB Cash | D7: Rp. 46.280 | E7: Rp. 45.835 | F7: Rp. 45.390 | G7: Rp. 44.945 | H7: Aktif
A8: VCPB12000-S7 | B8: Voucher Point Blank | C8: 12000 PB Cash | D8: Rp. 91.600 | E8: Rp. 90.649 | F8: Rp. 89.760 | G8: Rp. 89.316 | H8: Aktif
A9: VCPB12000-S11 | B9: Voucher Point Blank | C9: 12000 PB Cash | D9: Rp. 92.560 | E9: Rp. 91.670 | F9: Rp. 90.780 | G9: Rp. 89.890 | H9: Aktif
A10: VCPB24000-S7 | B10: Voucher Point Blank | C10: 24000 PB Cash | D10: Rp. 183.100 | E10: Rp. 181.297 | F10: Rp. 179.520 | G10: Rp. 178.631 | H10: Aktif
A11: VCPB24000-S11 | B11: Voucher Point Blank | C11: 24000 PB Cash | D11: Rp. 184.400 | E11: Rp. 182.619 | F11: Rp. 180.846 | G11: Rp. 179.073 | H11: Aktif
A12: VCPB36000-S7 | B12: Voucher Point Blank | C12: 36000 PB Cash | D12: Rp. 274.700 | E12: Rp. 271.947 | F12: Rp. 269.281 | G12: Rp. 267.948 | H12: Aktif
... A15: VCPB60000-S11 | B15: Voucher Point Blank | C15: 60000 PB Cash | D15: Rp. 460.900 | E15: Rp. 456.393 | F15: Rp. 451.962 | G15: Rp. 447.531 | H15: Aktif

Sheet PointBlank OURA STORE
A1: Voucher
A2: Select a variant list
A3: 1200 Cash
A4: 9790
A5: 2400 Cash
A6: 19580
A7: 6000 Cash
A8: 48950
A9: 12000 Cash
A10: 97900
A11: 24000 Cash
A12: 195800
A13: 36000 Cash
A14: 293700
A15: 60000 Cash
A16: 489500

Sheet VALO VOUCHER INDOFLAZ
A1: PID | B1: KATEGORI | C1: LAYANAN | D1: HARGA | E1: HARGA SILVER | F1: HARGA GOLD | G1: HARGA PRO | H1: STATUS
A2: VRC45S11 | B2: Voucher Valorant | C2: Riot Cash 45000 | D2: Rp. 44.041 | E2: Rp. 43.041 | F2: Rp. 42.541 | G2: Rp. 42.166 | H2: Aktif
A3: VRC75S11 | B3: Voucher Valorant | C3: Riot Cash 75000 | D3: Rp. 72.069 | E3: Rp. 71.069 | F3: Rp. 70.569 | G3: Rp. 70.194 | H3: Aktif
A4: VRC149S11 | B4: Voucher Valorant | C4: Riot Cash 149000 | D4: Rp. 141.203 | E4: Rp. 140.203 | F4: Rp. 139.703 | G4: Rp. 139.328 | H4: Aktif
A5: VRC219S11 | B5: Voucher Valorant | C5: Riot Cash 219000 | D5: Rp. 206.601 | E5: Rp. 205.601 | F5: Rp. 205.101 | G5: Rp. 204.726 | H5: Aktif
A6: VRC359S11 | B6: Voucher Valorant | C6: Riot Cash 359000 | D6: Rp. 337.396 | E6: Rp. 336.396 | F6: Rp. 335.896 | G6: Rp. 335.521 | H6: Aktif
A7: VRC739S11 | B7: Voucher Valorant | C7: Riot Cash 739000 | D7: Rp. 692.411 | E7: Rp. 691.411 | F7: Rp. 690.911 | G7: Rp. 690.536 | H7: Aktif

Sheet Google Play Gift Card INDOFLAZ
A1: PID | B1: KATEGORI | C1: LAYANAN | D1: HARGA | E1: HARGA SILVER | F1: HARGA GOLD | G1: HARGA PRO | H1: STATUS
A2: VGP100000-S11 | B2: Google Play Gift Card | C2: 100.000 IDR | D2: Rp. 99.210 | E2: Rp. 98.960 | F2: Rp. 98.760 | G2: Rp. 98.560 | H2: Aktif

Sheet Google Play Us Region INDOFLAZ
A1: PID | B1: KATEGORI | C1: LAYANAN | D1: HARGA | E1: HARGA SILVER | F1: HARGA GOLD | G1: HARGA PRO | H1: STATUS
A2: GPCUS10-S9 | B2: Google Play Us Region | C2: 10$ USA REGION | D2: Rp. 174.875 | E2: Rp. 174.625 | F2: Rp. 174.425 | G2: Rp. 174.225 | H2: Aktif
A3: GPCUS15-S9 | B3: Google Play Us Region | C3: 15$ USA REGION | D3: Rp. 240.750 | E3: Rp. 240.500 | F3: Rp. 240.300 | G3: Rp. 240.100 | H3: Aktif
A4: GPCUS25-S9 | B4: Google Play Us Region | C4: 25$ USA REGION | D4: Rp. 415.750 | E4: Rp. 415.500 | F4: Rp. 415.300 | G4: Rp. 415.100 | H4: Aktif
A5: GPCUS1000-S9 | B5: Google Play Us Region | C5: 100$ USA REGION | D5: Rp. 1.350.750 | E5: Rp. 1.350.500 | F5: Rp. 1.350.300 | G5: Rp. 1.350.100 | H5: Aktif

Sheet Google Play Gift Card OURA STOR
A1: Voucher
A2: Select a variant list
A3: 16.000 IDR
A4: 16437
A5: 35.000 IDR
A6: 35956
A7: 49.000 IDR
A8: 50339
A9: 65.000 IDR
A10: 66775
A11: 79.000 IDR
A12: 81157
A13: 150.000 IDR
A14: 154095
A15: 159.000 IDR
A16: 163342
A17: 249.000 IDR
A18: 255798
A19: 300.000 IDR
A20: 308190
A21: 329.000 IDR
A22: 337982
A23: 399.000 IDR
A24: 409893
A25: 500.000 IDR
A26: 513651
A27: 649.000 IDR
A28: 666718
A29: 799.000 IDR
A30: 820813
A31: 1.000.000 IDR
A32: 1027301
A33: 1.599.000 IDR
A34: 1642653

Sheet iTunes INDOFLAZ
A1: PID | B1: KATEGORI | C1: LAYANAN | D1: HARGA | E1: HARGA SILVER | F1: HARGA GOLD | G1: HARGA PRO | H1: STATUS
A2: FF5YAHAHA | B2: Itunes Us Region | C2: 5 Diamond | D2: Rp. 1.050 | E2: Rp. 1.040 | F2: Rp. 1.030 | G2: Rp. 1.020 | H2: Aktif
A3: VIT5-S9 | B3: Itunes Us Region | C3: US Region $5 | D3: Rp. 87.043 | E3: Rp. 86.793 | F3: Rp. 86.593 | G3: Rp. 86.393 | H3: Aktif
A4: VIT10-S9 | B4: Itunes Us Region | C4: US Region 10$ | D4: Rp. 173.311 | E4: Rp. 173.061 | F4: Rp. 172.861 | G4: Rp. 172.661 | H4: Aktif
A5: VIT15-S9 | B5: Itunes Us Region | C5: US Region $15 | D5: Rp. 210.775 | E5: Rp. 210.525 | F5: Rp. 210.325 | G5: Rp. 210.125 | H5: Aktif
A6: VIT25-S9 | B6: Itunes Us Region | C6: US Region $25 | D6: Rp. 383.550 | E6: Rp. 383.300 | F6: Rp. 383.100 | G6: Rp. 382.900 | H6: Aktif
A7: VIT50-S9 | B7: Itunes Us Region | C7: US Region $50 | D7: Rp. 780.750 | E7: Rp. 780.500 | F7: Rp. 780.300 | G7: Rp. 780.100 | H7: Aktif
A8: VIT100-S9 | B8: Itunes Us Region | C8: US Region $100 | D8: Rp. 1.718.215 | E8: Rp. 1.717.965 | F8: Rp. 1.717.765 | G8: Rp. 1.717.565 | H8: Aktif

Sheet Steam Wallet  INDOFLAZ
A1: PID | B1: KATEGORI | C1: LAYANAN | D1: HARGA | E1: HARGA SILVER | F1: HARGA GOLD | G1: HARGA PRO | H1: STATUS
A2: STEAM12-S11 | B2: Steam Wallet (IDR) | C2: IDR 12.000 STEAM | D2: Rp. 11.900 | E2: Rp. 11.800 | F2: Rp. 11.700 | G2: Rp. 11.600 | H2: Aktif
A3: STEAM45-S11 | B3: Steam Wallet (IDR) | C3: IDR 45.000 STEAM | D3: Rp. 46.000 | E3: Rp. 45.593 | F3: Rp. 45.343 | G3: Rp. 44.943 | H3: Aktif
A4: STEAM60-S11 | B4: Steam Wallet (IDR) | C4: IDR 60.000 STEAM | D4: Rp. 59.300 | E4: Rp. 58.966 | F4: Rp. 58.766 | G4: Rp. 58.566 | H4: Aktif
A5: STEAM90-S11 | B5: Steam Wallet (IDR) | C5: IDR 90.000 STEAM | D5: Rp. 89.700 | E5: Rp. 89.437 | F5: Rp. 89.237 | G5: Rp. 89.037 | H5: Aktif
A6: STEAM120-S11 | B6: Steam Wallet (IDR) | C6: IDR 120.000 STEAM | D6: Rp. 121.100 | E6: Rp. 120.582 | F6: Rp. 120.082 | G6: Rp. 119.682 | H6: Aktif
A7: STEAM250-S11 | B7: Steam Wallet (IDR) | C7: IDR 250.000 STEAM | D7: Rp. 250.100 | E7: Rp. 249.019 | F7: Rp. 248.019 | G7: Rp. 247.519 | H7: Aktif
A8: STEAM400-S11 | B8: Steam Wallet (IDR) | C8: IDR 400.000 STEAM | D8: Rp. 400.100 | E8: Rp. 398.045 | F8: Rp. 396.045 | G8: Rp. 395.545 | H8: Aktif
A9: STEAM600-S11 | B9: Steam Wallet (IDR) | C9: IDR 600.000 STEAM | D9: Rp. 599.700 | E9: Rp. 594.659 | F9: Rp. 589.659 | G9: Rp. 586.659 | H9: Aktif

Sheet Steam Wallet OURA STORE
A1: Voucher Indonesia (IDR)
A2: Select a variant list
A3: 12.000 IDR
A4: 13753
A5: 60.000 IDR
A6: 68763
A7: 90.000 IDR
A8: 98037
A9: 120.000 IDR
A10: 137524
A11: 250.000 IDR
A12: 286508
A13: 400.000 IDR
A14: 458412
A15: 600.000 IDR
A16: 687616

Sheet Spotify Premium Subscription Vo
A1: PID | B1: KATEGORI | C1: LAYANAN | D1: HARGA | E1: HARGA SILVER | F1: HARGA GOLD | G1: HARGA PRO | H1: STATUS
A2: SPSV1-S9 | B2: Spotify | C2: Spotify Premium Subscription Voucher - 1 Bulan | D2: Rp. 56.820 | E2: Rp. 56.570 | F2: Rp. 56.370 | G2: Rp. 56.170 | H2: Aktif
A3: SPSV3-S9 | B3: Spotify | C3: Spotify Premium Subscription Voucher - 3 Bulan | D3: Rp. 166.075 | E3: Rp. 165.825 | F3: Rp. 165.625 | G3: Rp. 165.425 | H3: Aktif
A4: SPSV6-S9 | B4: Spotify | C4: Spotify Premium Subscription Voucher - 6 Bulan | D4: Rp. 303.675 | E4: Rp. 303.425 | F4: Rp. 303.225 | G4: Rp. 303.025 | H4: Aktif

Sheet Nintendo Eshop
A1: PID | B1: KATEGORI | C1: LAYANAN | D1: HARGA | E1: HARGA SILVER | F1: HARGA GOLD | G1: HARGA PRO | H1: STATUS
A2: VNTD10-S11 | B2: Nintendo Eshop | C2: Nintendo $10 | D2: Rp. 137.342 | E2: Rp. 137.092 | F2: Rp. 136.892 | G2: Rp. 136.692 | H2: Aktif
A3: VNTD50-S11 | B3: Nintendo Eshop | C3: Nintendo $50 | D3: Rp. 675.582 | E3: Rp. 675.332 | F3: Rp. 675.132 | G3: Rp. 674.932 | H3: Aktif

Sheet Vidio INDOFLAZ
A1: PID | B1: KATEGORI | C1: LAYANAN | D1: HARGA | E1: HARGA SILVER | F1: HARGA GOLD | G1: HARGA PRO | H1: STATUS
A2: VIDEPLBASIC30-S11 | B2: Vidio | C2: EPL Basic 30D | D2: Rp. 24.850 | E2: Rp. 24.600 | F2: Rp. 24.400 | G2: Rp. 24.200 | H2: Aktif
A3: VIDPDU17P-S11 | B3: Vidio | C3: FIFA U-17 World Cup Indonesia 2023 | D3: Rp. 38.050 | E3: Rp. 37.800 | F3: Rp. 37.600 | G3: Rp. 37.400 | H3: Aktif
A4: VIDPLATINUM30D-S11 | B4: Vidio | C4: Platinum 30 Hari | D4: Rp. 45.000 | E4: Rp. 44.700 | F4: Rp. 44.500 | G4: Rp. 44.300 | H4: Aktif
A5: VIDDIAMONDMOBILE30D-S11 | B5: Vidio | C5: Diamond Mobile 30 Hari | D5: Rp. 47.550 | E5: Rp. 47.300 | F5: Rp. 47.100 | G5: Rp. 46.900 | H5: Aktif
A6: VIDDIAMONDMOBILE30D-S110 | B6: Vidio | C6: Diamond Mobile 30 Hari | D6: Rp. 48.885 | E6: Rp. 48.635 | F6: Rp. 48.435 | G6: Rp. 48.235 | H6: Aktif
A7: VIDDIAMONDALLSCREEN30D-S11 | B7: Vidio | C7: Diamond All Screen 30 Hari | D7: Rp. 95.350 | E7: Rp. 95.100 | F7: Rp. 94.900 | G7: Rp. 94.700 | H7: Aktif
A8: VIDDIAMONDALLSCREEN30D-S110 | B8: Vidio | C8: Diamond All Screen 30 Hari | D8: Rp. 96.398 | E8: Rp. 96.148 | F8: Rp. 95.948 | G8: Rp. 95.748 | H8: Aktif
A9: VIDPLATINUM1YR-S11 | B9: Vidio | C9: Platinum 1 Tahun | D9: Rp. 259.150 | E9: Rp. 258.900 | F9: Rp. 258.700 | G9: Rp. 258.500 | H9: Aktif
A10: VIDPLATINUM1YR-S110 | B10: Vidio | C10: Platinum 1 Tahun | D10: Rp. 262.245 | E10: Rp. 261.995 | F10: Rp. 261.795 | G10: Rp. 261.595 | H10: Aktif
A11: VIDDIAMONDMOBILE1YR-S11 | B11: Vidio | C11: Diamond Mobile 1 Tahun | D11: Rp. 413.450 | E11: Rp. 413.200 | F11: Rp. 413.000 | G11: Rp. 412.800 | H11: Aktif
A12: VIDDIAMONDMOBILE1YR-S110 | B12: Vidio | C12: Diamond Mobile 1 Tahun | D12: Rp. 418.440 | E12: Rp. 418.190 | F12: Rp. 417.990 | G12: Rp. 417.790 | H12: Aktif
... A14: VIDDIAMONDALLSCREEN1YR-S110 | B14: Vidio | C14: Diamond All Screen 1 Tahun | D14: Rp. 721.275 | E14: Rp. 721.025 | F14: Rp. 720.825 | G14: Rp. 720.625 | H14: Aktif

Sheet Vidio OURA STORE
A1: Voucher
A2: Select a variant list
A3: Diamond All Screen 30 Hari
A4: 142212
A5: Diamond Mobile 1 Tahun
A6: 443819
A8: Top Up Instant
A9: Select a variant list
A10: Platinum 30 Days
A11: 41475
A12: Platinum Extra 30 Days
A13: 60327
A14: Ultimate Mobile 30 Days
A15: 91328
A16: Platinum 3 Months
A17: 98870
A18: Platinum Extra 3 Months
A19: 142438
A20: Ultimate All Screen 30 Days
A21: 162548
A22: Ultimate Mobile 3 Months
A23: 222037
A24: Platinum 1 Year
A25: 300796
A26: Ultimate All Screen 3 Months
A27: 389610
A28: Platinum Extra 1 Year
A29: 435693
A30: Ultimate Mobile 1 Year
A31: 719730
A32: Ultimate All Screen 1 Year
A33: 1268534

Sheet Xbox Indoflaz
A1: PID | B1: KATEGORI | C1: LAYANAN | D1: HARGA | E1: HARGA SILVER | F1: HARGA GOLD | G1: HARGA PRO | H1: STATUS
A2: XBOXGPU1-S11 | B2: Xbox | C2: Xbox Game Pass Ultimate 1 Month | D2: Rp. 212.950 | E2: Rp. 212.700 | F2: Rp. 212.500 | G2: Rp. 212.300 | H2: Aktif
A3: XBOXUSDM3-S11 | B3: Xbox | C3: Xbox Membership 3 Months | D3: Rp. 354.450 | E3: Rp. 354.200 | F3: Rp. 354.000 | G3: Rp. 353.800 | H3: Aktif
A4: XBOXEAPM12-S11 | B4: Xbox | C4: EA Play Membership 12 Months | D4: Rp. 383.950 | E4: Rp. 383.700 | F4: Rp. 383.500 | G4: Rp. 383.300 | H4: Aktif
A5: XBOXGPU3-S11 | B5: Xbox | C5: Xbox Game Pass Ultimate 3 Months | D5: Rp. 637.350 | E5: Rp. 637.100 | F5: Rp. 636.900 | G5: Rp. 636.700 | H5: Aktif
A6: XBOXUSDM12-S11 | B6: Xbox | C6: Xbox Membership 12 Months | D6: Rp. 849.450 | E6: Rp. 849.200 | F6: Rp. 849.000 | G6: Rp. 848.800 | H6: Aktif
A7: XBOXUSDGP1-S11 | B7: Xbox | C7: Xbox Game Pass 6 Months | D7: Rp. 849.450 | E7: Rp. 849.200 | F7: Rp. 849.000 | G7: Rp. 848.800 | H7: Aktif

Sheet Hotelmurah INDOLAZ
A1: PID | B1: KATEGORI | C1: LAYANAN | D1: HARGA | E1: HARGA SILVER | F1: HARGA GOLD | G1: HARGA PRO | H1: STATUS
A2: HTL40-S9 | B2: Hotelmurah | C2: voucher Hotel Hotelmurah 50.000 | D2: Rp. 42.000 | E2: Rp. 41.600 | F2: Rp. 41.200 | G2: Rp. 40.800 | H2: Aktif
A3: HTL100-S9 | B3: Hotelmurah | C3: Voucher Hotel Hotelmurah 100.000 | D3: Rp. 94.500 | E3: Rp. 93.600 | F3: Rp. 92.700 | G3: Rp. 91.800 | H3: Aktif
A4: HTL200-S9 | B4: Hotelmurah | C4: Voucher Hotel Hotelmurah 200.000 | D4: Rp. 198.500 | E4: Rp. 196.560 | F4: Rp. 194.670 | G4: Rp. 192.780 | H4: Aktif
A5: HTL500-S9 | B5: Hotelmurah | C5: Voucher Hotel Hotelmurah 500.000 | D5: Rp. 509.300 | E5: Rp. 504.400 | F5: Rp. 499.550 | G5: Rp. 494.700 | H5: Aktif
A6: HTL1000-S9 | B6: Hotelmurah | C6: Voucher Hotel Hotelmurah 1.000.000 | D6: Rp. 1.029.000 | E6: Rp. 1.019.200 | F6: Rp. 1.009.400 | G6: Rp. 999.600 | H6: Aktif

Sheet Gontak Whatsapp dan SMS Gateway
A1: PID | B1: KATEGORI | C1: LAYANAN | D1: HARGA | E1: HARGA SILVER | F1: HARGA GOLD | G1: HARGA PRO | H1: STATUS
A2: GNTKPRO | B2: Gontak Whatsapp dan SMS Gateway | C2: Paket Professional | D2: Rp. 25.000 | E2: Rp. 25.000 | F2: Rp. 25.000 | G2: Rp. 25.000 | H2: Aktif
A3: GNTKENTR | B3: Gontak Whatsapp dan SMS Gateway | C3: Paket Enterprise | D3: Rp. 50.000 | E3: Rp. 50.000 | F3: Rp. 50.000 | G3: Rp. 50.000 | H3: Aktif
A4: GNTKBOGO | B4: Gontak Whatsapp dan SMS Gateway | C4: Paket VIP BOGO | D4: Rp. 80.000 | E4: Rp. 80.000 | F4: Rp. 80.000 | G4: Rp. 80.000 | H4: Aktif

Sheet PLN INDOFLAZ
A1: PID | B1: KATEGORI | C1: LAYANAN | D1: HARGA | E1: HARGA SILVER | F1: HARGA GOLD | G1: HARGA PRO | H1: STATUS
A2: PLN20 | B2: PLN | C2: PLN 20.000 | D2: Rp. 22.100 | E2: Rp. 21.935 | F2: Rp. 21.785 | G2: Rp. 21.685 | H2: Aktif
A3: PLN50 | B3: PLN | C3: PLN 50.000 | D3: Rp. 52.200 | E3: Rp. 52.003 | F3: Rp. 51.853 | G3: Rp. 51.753 | H3: Aktif
A4: PLN100 | B4: PLN | C4: PLN 100.000 | D4: Rp. 102.200 | E4: Rp. 101.975 | F4: Rp. 101.825 | G4: Rp. 101.725 | H4: Aktif
A5: PLN200 | B5: PLN | C5: PLN 200.000 | D5: Rp. 202.200 | E5: Rp. 202.030 | F5: Rp. 201.880 | G5: Rp. 201.780 | H5: Aktif
A6: PLN500 | B6: PLN | C6: PLN 500.000 | D6: Rp. 502.200 | E6: Rp. 501.975 | F6: Rp. 501.825 | G6: Rp. 501.725 | H6: Aktif
A7: PLN1000 | B7: PLN | C7: PLN 1.000.000 | D7: Rp. 1.002.300 | E7: Rp. 1.002.100 | F7: Rp. 1.001.950 | G7: Rp. 1.001.850 | H7: Aktif

Sheet Pulsa Telkomsel INDOFLAZ
A1: PID | B1: KATEGORI | C1: LAYANAN | D1: HARGA | E1: HARGA SILVER | F1: HARGA GOLD | G1: HARGA PRO | H1: STATUS
A2: TSL10 | B2: Telkomsel | C2: Telkomsel 10.000 | D2: Rp. 10.522 | E2: Rp. 10.420 | F2: Rp. 10.318 | G2: Rp. 10.267 | H2: Aktif
A3: TSL10-S9 | B3: Telkomsel | C3: Telkomsel 10.000 | D3: Rp. 10.965 | E3: Rp. 10.715 | F3: Rp. 10.515 | G3: Rp. 10.315 | H3: Aktif
A4: TSL15 | B4: Telkomsel | C4: Telkomsel 15.000 | D4: Rp. 15.327 | E4: Rp. 15.178 | F4: Rp. 15.029 | G4: Rp. 14.955 | H4: Aktif
A5: TSL15-S9 | B5: Telkomsel | C5: Telkomsel 15.000 | D5: Rp. 15.630 | E5: Rp. 15.380 | F5: Rp. 15.180 | G5: Rp. 14.980 | H5: Aktif
A6: TSL20 | B6: Telkomsel | C6: Telkomsel 20.000 | D6: Rp. 20.286 | E6: Rp. 20.089 | F6: Rp. 19.892 | G6: Rp. 19.794 | H6: Aktif
A7: TSL20-S9 | B7: Telkomsel | C7: Telkomsel 20.000 | D7: Rp. 20.445 | E7: Rp. 20.195 | F7: Rp. 19.995 | G7: Rp. 19.795 | H7: Aktif
A8: TSL25 | B8: Telkomsel | C8: Telkomsel 25.000 | D8: Rp. 25.663 | E8: Rp. 25.414 | F8: Rp. 25.165 | G8: Rp. 25.040 | H8: Aktif
A9: TSL25-S9 | B9: Telkomsel | C9: Telkomsel 25.000 | D9: Rp. 25.665 | E9: Rp. 25.415 | F9: Rp. 25.215 | G9: Rp. 25.015 | H9: Aktif
A10: TSL30-S9 | B10: Telkomsel | C10: Telkomsel 30.000 | D10: Rp. 30.175 | E10: Rp. 29.925 | F10: Rp. 29.725 | G10: Rp. 29.525 | H10: Aktif
A11: TSL30 | B11: Telkomsel | C11: Telkomsel 30.000 | D11: Rp. 30.308 | E11: Rp. 30.014 | F11: Rp. 29.720 | G11: Rp. 29.573 | H11: Aktif
A12: TSL40-S9 | B12: Telkomsel | C12: Telkomsel 40.000 | D12: Rp. 40.475 | E12: Rp. 40.225 | F12: Rp. 40.025 | G12: Rp. 39.825 | H12: Aktif
... A36: TSL1000 | B36: Telkomsel | C36: Telkomsel 1.000.000 | D36: Rp. 1.025.391 | E36: Rp. 1.015.436 | F36: Rp. 1.005.481 | G36: Rp. 1.000.503 | H36: Aktif

Sheet Pulsa Telkomsel OURA STORE
A1: Pulsa Reguler
A2: Select a variant list
A3: Pulsa 10.000
A4: 12297
A5: Pulsa 20.000
A6: 21999
A7: Pulsa 25.000
A8: 26986
A9: Pulsa 30.000
A10: 31762
A11: Pulsa 35.000
A12: 36975
A13: Pulsa 40.000
A14: 41494
A15: Pulsa 45.000
A16: 46950
A17: Pulsa 50.000
A18: 51907
A19: Pulsa 55.000
A20: 56944
A21: Pulsa 60.000
A22: 61911
A23: Pulsa 65.000
A24: 66893
A25: Pulsa 70.000
A26: 71875
A27: Pulsa 75.000
A28: 75487
A29: Pulsa 80.000
A30: 81849
A31: Pulsa 85.000
A32: 86832
A33: Pulsa 90.000
A34: 91819
A35: Pulsa 95.000
A36: 96811
A37: Pulsa 150.000
A38: 148264
A39: Pulsa 200.000
A40: 197934
...

Sheet byU INDOFLAZ
A1: PID | B1: KATEGORI | C1: LAYANAN | D1: HARGA | E1: HARGA SILVER | F1: HARGA GOLD | G1: HARGA PRO | H1: STATUS
A2: BYU10-S9 | B2: byU | C2: by.U 10.000 | D2: Rp. 10.765 | E2: Rp. 10.515 | F2: Rp. 10.315 | G2: Rp. 10.115 | H2: Aktif
A3: BYU15-S9 | B3: byU | C3: by.U 15.000 | D3: Rp. 15.680 | E3: Rp. 15.430 | F3: Rp. 15.230 | G3: Rp. 15.030 | H3: Aktif
A4: BYU20-S9 | B4: byU | C4: by.U 20.000 | D4: Rp. 20.585 | E4: Rp. 20.335 | F4: Rp. 20.135 | G4: Rp. 19.935 | H4: Aktif
A5: BYU25-S9 | B5: byU | C5: by.U 25.000 | D5: Rp. 25.485 | E5: Rp. 25.235 | F5: Rp. 25.035 | G5: Rp. 24.835 | H5: Aktif
A6: BYU30-S9 | B6: byU | C6: by.U 30.000 | D6: Rp. 30.275 | E6: Rp. 30.025 | F6: Rp. 29.825 | G6: Rp. 29.625 | H6: Aktif
A7: BYU35-S9 | B7: byU | C7: by.U 35.000 | D7: Rp. 35.480 | E7: Rp. 35.230 | F7: Rp. 35.030 | G7: Rp. 34.830 | H7: Aktif
A8: BYU40-S9 | B8: byU | C8: by.U 40.000 | D8: Rp. 40.625 | E8: Rp. 40.375 | F8: Rp. 40.175 | G8: Rp. 39.975 | H8: Aktif
A9: BYU45-S9 | B9: byU | C9: by.U 45.000 | D9: Rp. 45.395 | E9: Rp. 45.145 | F9: Rp. 44.945 | G9: Rp. 44.745 | H9: Aktif
A10: BYU50-S9 | B10: byU | C10: by.U 50.000 | D10: Rp. 50.625 | E10: Rp. 50.375 | F10: Rp. 50.175 | G10: Rp. 49.975 | H10: Aktif
A11: BYU55-S9 | B11: byU | C11: by.U 55.000 | D11: Rp. 55.295 | E11: Rp. 55.045 | F11: Rp. 54.845 | G11: Rp. 54.645 | H11: Aktif
A12: BYU60-S9 | B12: byU | C12: by.U 60.000 | D12: Rp. 60.245 | E12: Rp. 59.995 | F12: Rp. 59.795 | G12: Rp. 59.595 | H12: Aktif
... A21: BYU150-S9 | B21: byU | C21: by.U 150.000 | D21: Rp. 149.475 | E21: Rp. 149.225 | F21: Rp. 149.025 | G21: Rp. 148.825 | H21: Aktif

Sheet Indosat INDOFLAZ
A1: PID | B1: KATEGORI | C1: LAYANAN | D1: HARGA | E1: HARGA SILVER | F1: HARGA GOLD | G1: HARGA PRO | H1: STATUS
A2: ISAT10-S9 | B2: Indosat | C2: Indosat 10.000 | D2: Rp. 11.580 | E2: Rp. 11.330 | F2: Rp. 11.130 | G2: Rp. 10.930 | H2: Aktif
A3: ISAT15-S9 | B3: Indosat | C3: Indosat 15.000 | D3: Rp. 15.650 | E3: Rp. 15.400 | F3: Rp. 15.200 | G3: Rp. 15.000 | H3: Aktif
A4: ISAT20-S9 | B4: Indosat | C4: Indosat 20.000 | D4: Rp. 20.300 | E4: Rp. 20.050 | F4: Rp. 19.850 | G4: Rp. 19.650 | H4: Aktif
A5: ISAT25-S9 | B5: Indosat | C5: Indosat 25.000 | D5: Rp. 25.615 | E5: Rp. 25.365 | F5: Rp. 25.165 | G5: Rp. 24.965 | H5: Aktif
A6: ISAT30-S9 | B6: Indosat | C6: Indosat 30.000 | D6: Rp. 30.415 | E6: Rp. 30.165 | F6: Rp. 29.965 | G6: Rp. 29.765 | H6: Aktif
A7: ISAT40-S9 | B7: Indosat | C7: Indosat 40.000 | D7: Rp. 40.300 | E7: Rp. 40.050 | F7: Rp. 39.850 | G7: Rp. 39.650 | H7: Aktif
A8: ISAT50-S9 | B8: Indosat | C8: Indosat 50.000 | D8: Rp. 49.875 | E8: Rp. 49.625 | F8: Rp. 49.425 | G8: Rp. 49.225 | H8: Aktif
A9: ISAT60-S9 | B9: Indosat | C9: Indosat 60.000 | D9: Rp. 59.750 | E9: Rp. 59.500 | F9: Rp. 59.300 | G9: Rp. 59.100 | H9: Aktif
A10: ISAT70-S9 | B10: Indosat | C10: Indosat 70.000 | D10: Rp. 68.740 | E10: Rp. 68.490 | F10: Rp. 68.290 | G10: Rp. 68.090 | H10: Aktif
A11: ISAT80-S9 | B11: Indosat | C11: Indosat 80.000 | D11: Rp. 79.075 | E11: Rp. 78.825 | F11: Rp. 78.625 | G11: Rp. 78.425 | H11: Aktif
A12: ISAT90-S9 | B12: Indosat | C12: Indosat 90.000 | D12: Rp. 87.695 | E12: Rp. 87.445 | F12: Rp. 87.245 | G12: Rp. 87.045 | H12: Aktif
... A20: ISAT1000-S9 | B20: Indosat | C20: Indosat 1.000.000 | D20: Rp. 928.250 | E20: Rp. 928.000 | F20: Rp. 927.800 | G20: Rp. 927.600 | H20: Aktif

Sheet Indosat OURA STORE
A1: Pulsa Reguler
A2: Select a variant list
A3: Indosat 5.000
A4: 7010
A5: Indosat 10.000
A6: 11970
A7: Indosat 12.000
A8: 13633
A9: Indosat 20.000
A10: 22501
A11: Indosat 25.000
A12: 26643
A13: Indosat 30.000
A14: 32376
A15: Indosat 40.000
A16: 41595
A17: Indosat 50.000
A18: 51069
A19: Indosat 60.000
A20: 61220
A21: Indosat 70.000
A22: 70868
A23: Indosat 80.000
A24: 80415
A25: Indosat 90.000
A26: 91234
A27: Indosat 100.000
A28: 98033
A29: Indosat 150.000
A30: 150589
A31: Indosat 200.000
A32: 198553
A33: Indosat 250.000
A34: 250903
A35: Indosat 500.000
A36: 498748
A37: Indosat 1.000.000
A38: 997000

Sheet Axis INDOFLAZ
A1: PID | B1: KATEGORI | C1: LAYANAN | D1: HARGA | E1: HARGA SILVER | F1: HARGA GOLD | G1: HARGA PRO | H1: STATUS
A2: AXIS10-S9 | B2: Axis | C2: Axis 10.000 | D2: Rp. 10.950 | E2: Rp. 10.700 | F2: Rp. 10.500 | G2: Rp. 10.300 | H2: Aktif
A3: AXIS15-S9 | B3: Axis | C3: Axis 15.000 | D3: Rp. 15.360 | E3: Rp. 15.110 | F3: Rp. 14.910 | G3: Rp. 14.710 | H3: Aktif
A4: AXIS25-S9 | B4: Axis | C4: Axis 25.000 | D4: Rp. 25.060 | E4: Rp. 24.810 | F4: Rp. 24.610 | G4: Rp. 24.410 | H4: Aktif
A5: AXIS30-S9 | B5: Axis | C5: Axis 30.000 | D5: Rp. 30.589 | E5: Rp. 30.339 | F5: Rp. 30.139 | G5: Rp. 29.939 | H5: Aktif
A6: AXIS50-S9 | B6: Axis | C6: Axis 50.000 | D6: Rp. 50.405 | E6: Rp. 50.155 | F6: Rp. 49.955 | G6: Rp. 49.755 | H6: Aktif
A7: AXIS100-S9 | B7: Axis | C7: Axis 100.000 | D7: Rp. 99.490 | E7: Rp. 99.240 | F7: Rp. 99.040 | G7: Rp. 98.840 | H7: Aktif
A8: AXIS200-S9 | B8: Axis | C8: Axis 200.000 | D8: Rp. 200.435 | E8: Rp. 200.185 | F8: Rp. 199.985 | G8: Rp. 199.785 | H8: Aktif
A9: AXIS300-S9 | B9: Axis | C9: Axis 300.000 | D9: Rp. 299.025 | E9: Rp. 298.775 | F9: Rp. 298.575 | G9: Rp. 298.375 | H9: Aktif
A10: AXIS500-S9 | B10: Axis | C10: Axis 500.000 | D10: Rp. 496.350 | E10: Rp. 496.100 | F10: Rp. 495.900 | G10: Rp. 495.700 | H10: Aktif
A11: AXIS1000-S9 | B11: Axis | C11: Axis 1.000.000 | D11: Rp. 994.460 | E11: Rp. 994.210 | F11: Rp. 994.010 | G11: Rp. 993.810 | H11: Aktif

Sheet Axis OURASTORE
A1: Pulsa Reguler
A2: Select a variant list
A3: Axis 5.000
A4: 7824
A5: Axis 10.000
A6: 12894
A7: Axis 15.000
A8: 17062
A9: Axis 25.000
A10: 27093
A11: Axis 50.000
A12: 52186
A13: Axis 100.000
A14: 102224

Sheet XL INDOFLAZ
A1: PID | B1: KATEGORI | C1: LAYANAN | D1: HARGA | E1: HARGA SILVER | F1: HARGA GOLD | G1: HARGA PRO | H1: STATUS
A2: XL15-S9 | B2: XL | C2: Xl 15.000 | D2: Rp. 15.445 | E2: Rp. 15.195 | F2: Rp. 14.995 | G2: Rp. 14.795 | H2: Aktif
A3: XL25-S9 | B3: XL | C3: Xl 25.000 | D3: Rp. 25.570 | E3: Rp. 25.320 | F3: Rp. 25.120 | G3: Rp. 24.920 | H3: Aktif
A4: XL30-S9 | B4: XL | C4: XL 30.000 | D4: Rp. 29.800 | E4: Rp. 29.550 | F4: Rp. 29.350 | G4: Rp. 29.150 | H4: Aktif
A5: XL40-S9 | B5: XL | C5: XL 40.000 | D5: Rp. 39.675 | E5: Rp. 39.425 | F5: Rp. 39.225 | G5: Rp. 39.025 | H5: Aktif
A6: XL50-S9 | B6: XL | C6: Xl 50.000 | D6: Rp. 48.750 | E6: Rp. 48.500 | F6: Rp. 48.300 | G6: Rp. 48.100 | H6: Aktif
A7: XL100-S9 | B7: XL | C7: Xl 100.000 | D7: Rp. 99.525 | E7: Rp. 99.275 | F7: Rp. 99.075 | G7: Rp. 98.875 | H7: Aktif
A8: XL150-S9 | B8: XL | C8: Xl 150.000 | D8: Rp. 150.060 | E8: Rp. 149.810 | F8: Rp. 149.610 | G8: Rp. 149.410 | H8: Aktif
A9: XL200-S9 | B9: XL | C9: Xl 200.000 | D9: Rp. 199.590 | E9: Rp. 199.340 | F9: Rp. 199.140 | G9: Rp. 198.940 | H9: Aktif
A10: XL300-S9 | B10: XL | C10: Xl 300.000 | D10: Rp. 299.350 | E10: Rp. 299.100 | F10: Rp. 298.900 | G10: Rp. 298.700 | H10: Aktif
A11: XL500-S9 | B11: XL | C11: Xl 500.000 | D11: Rp. 498.400 | E11: Rp. 498.150 | F11: Rp. 497.950 | G11: Rp. 497.750 | H11: Aktif
A12: XL1000-S9 | B12: XL | C12: Xl 1.000.000 | D12: Rp. 993.875 | E12: Rp. 993.625 | F12: Rp. 993.425 | G12: Rp. 993.225 | H12: Aktif

Sheet XL OURASTORE
A1: Pulsa Reguler
A2: Select a variant list
A3: Xl 5.000
A4: 7528
A5: XL 10.000
A6: 12748
A7: XL 15.000
A8: 17013
A9: XL 25.000
A10: 27049
A11: XL 50.000
A12: 52320
A13: XL 100.000
A14: 102498

Sheet TRI INDOFLAZ
A1: PID | B1: KATEGORI | C1: LAYANAN | D1: HARGA | E1: HARGA SILVER | F1: HARGA GOLD | G1: HARGA PRO | H1: STATUS
A2: TRI10-S9 | B2: TRI | C2: Three 10.000 | D2: Rp. 11.107 | E2: Rp. 10.857 | F2: Rp. 10.657 | G2: Rp. 10.457 | H2: Aktif
A3: TRI15-S9 | B3: TRI | C3: Three 15.000 | D3: Rp. 15.583 | E3: Rp. 15.333 | F3: Rp. 15.133 | G3: Rp. 14.933 | H3: Aktif
A4: TRI20-S9 | B4: TRI | C4: Three 20.000 | D4: Rp. 20.400 | E4: Rp. 20.150 | F4: Rp. 19.950 | G4: Rp. 19.750 | H4: Aktif
A5: TRI25-S9 | B5: TRI | C5: Three 25.000 | D5: Rp. 25.494 | E5: Rp. 25.244 | F5: Rp. 25.044 | G5: Rp. 24.844 | H5: Aktif
A6: TRI30-S9 | B6: TRI | C6: Three 30.000 | D6: Rp. 30.275 | E6: Rp. 30.025 | F6: Rp. 29.825 | G6: Rp. 29.625 | H6: Aktif
